Workbook
Name dateperiod: [1]!Table1[period]

Sheet Mapping
A1: Name | B1: United Components
A2: ds_gross_sales | B2: Gross Sales | C2: ds_gross_sales | D2: Gross Sales | E2: Variance
A3: ds_inelig_state | B3: Direct Sales to Non-Domestic Customers | C3: ds_inelig_state | D3: Direct Sales to Non-Domestic Customers | E3: Variance
A4: ds_inelig_cot | B4: Direct Sales to Ineligible Customers (COT) | C4: ds_inelig_cot | D4: Direct Sales to Ineligible Customers (COT) | E4: Variance
A5: ds_inelig_cont | B5: Direct Sales to Ineligible Customers (Contract) | C5: ds_inelig_cont | D5: Direct Sales to Ineligible Customers (Contract) | E5: Variance
A6: ds_free_goods | B6: Ineligible Free Goods | C6: ds_free_goods | D6: Ineligible Free Goods | E6: Variance
A7: ds_inelig_340b | B7: RHAP Sales to 340B Eligible Customers | C7: ds_inelig_340b | D7: RHAP Sales to 340B Eligible Customers | E7: Variance
A8: ds_elig | B8: Eligible Direct Sales | C8: ds_elig | D8: Eligible Direct Sales | E8: Variance
A9: ds_elig_adj | B9: Eligible Credits and Adjustments | C9: ds_elig_adj | D9: Eligible Credits and Adjustments | E9: Variance
A10: cbk_cont_inelig_12m | B10: 12-Month Total : Ineligible Contract Chargeback Qty | C10: cbk_cont_inelig_12m | D10: 12-Month Total : Ineligible Contract Chargeback Qty | E10: Variance
A11: cbk_state_inelig_12m | B11: 12-Month Total : Ineligible State Chargeback Qty | C11: cbk_state_inelig_12m | D11: 12-Month Total : Ineligible State Chargeback Qty | E11: Variance
A12: cbk_cot_inelig_12m | B12: 12-Month Total : Ineligible Cot Chargeback Qty | C12: cbk_cot_inelig_12m | D12: 12-Month Total : Ineligible Cot Chargeback Qty | E12: Variance
A13: avg_ds_elig | B13: Cur. Average Direct Price | C13: avg_ds_elig | D13: Cur. Average Direct Price | E13: Variance
... A26: ramp | B26: AMP (NDC9) | C26: ramp | D26: AMP (NDC9) | E26: Variance

Sheet United MAMP All Components
A1: NDC11 | B1: Gross Sales - Dollars | C1: Gross Sales - Units | D1: Gross Sales - Price/Unit | E1: Direct Sales to Non-Domestic Customers - Dollars | F1: Direct Sales to Non-Domestic Customers - Units | G1: Direct Sales to Non-Domestic Customers - Price/Unit | H1: Direct Sales to Ineligible Customers (COT) - Dollars | I1: Direct Sales to Ineligible Customers (COT) - Units | J1: Direct Sales to Ineligible Customers (COT) - Price/Unit | K1: Direct Sales to Ineligible Customers (Contract) - Dollars | L1: Direct Sales to Ineligible Customers (Contract) - Units | M1: Direct Sales to Ineligible Customers (Contract) - Price/Unit | N1: Ineligible Free Goods - Dollars | O1: Ineligible Free Goods - Units | P1: Ineligible Free Goods - Price/Unit | Q1: RHAP Sales to 340B Eligible Customers - Dollars | R1: RHAP Sales to 340B Eligible Customers - Units | S1: RHAP Sales to 340B Eligible Customers - Price/Unit | T1: Eligible Direct Sales - Dollars | U1: Eligible Direct Sales - Units | V1: Eligible Direct Sales - Price/Unit | W1: Smoothed Indirect Ineligible Sales-State - Dollars | X1: Smoothed Indirect Ineligible Sales-State - Units | Y1: Smoothed Indirect Ineligible Sales-State - Price/Unit | Z1: Smoothed Indirect Ineligible Sales-COT - Dollars | AA1: Smoothed Indirect Ineligible Sales-COT - Units | AB1: Smoothed Indirect Ineligible Sales-COT - Price/Unit | AC1: Smoothed Indirect Ineligible Sales-Contract - Dollars | AD1: Smoothed Indirect Ineligible Sales-Contract - Units | AE1: Smoothed Indirect Ineligible Sales-Contract - Price/Unit | AF1: Smoothed Indirect Ineligible Sales-Mail Order - Dollars | AG1: Smoothed Indirect Ineligible Sales-Mail Order - Units | AH1: Smoothed Indirect Ineligible Sales-Mail Order - Price/Unit | AI1: Smoothed Indirect Ineligible Dollars(ndc11) - Dollars | AJ1: Smoothed Indirect Ineligible Dollars(ndc11) - Units | AK1: Smoothed Indirect Ineligible Dollars(ndc11) - Price/Unit | AL1: AMP Eligible Sales - Dollars | AM1: AMP Eligible Sales - Units | AN1: AMP Eligible Sales - Price/Unit | AO1: Eligible Credits and Adjustments - Dollars | AP1: Eligible Credits and Adjustments - Units | AQ1: Eligible Credits and Adjustments - Price/Unit | AR1: Adjusted AMP Eligible Sales - Dollars | AS1: Adjusted AMP Eligible Sales - Units | AT1: Adjusted AMP Eligible Sales - Price/Unit | AU1: Adjusted AMP Eligible Sales (NDC9) - Dollars | AV1: Adjusted AMP Eligible Sales (NDC9) - Units | AW1: Adjusted AMP Eligible Sales (NDC9) - Price/Unit | AX1: Smoothed Price Concessions - Dollars | AY1: Smoothed Price Concessions - Units | AZ1: Smoothed Price Concessions - Price/Unit | BA1: CPPD to Non-Wholesalers - Dollars | BB1: CPPD to Non-Wholesalers - Units | BC1: CPPD to Non-Wholesalers - Price/Unit | BD1: Net NDC9 AMP Eligible Sales - Dollars | BE1: Net NDC9 AMP Eligible Sales - Units | BF1: Net NDC9 AMP Eligible Sales - Price/Unit | BG1: AMP (NDC9) - Dollars | BH1: AMP (NDC9) - Units | BI1: AMP (NDC9) - Price/Unit
A2: 66302001401 | B2: 27,730,336.00 | C2: 8,000.00 | D2: 3,466.292000 | E2: 0.00 | F2: 0.00 | G2: 0.000000 | H2: 0.00 | I2: 0.00 | J2: 0.000000 | K2: 0.00 | L2: 0.00 | M2: 0.000000 | N2: 0.00 | O2: 0.00 | P2: 0.000000 | Q2: 0.00 | R2: 0.00 | S2: 0.000000 | T2: 27,730,336.00 | U2: 8,000.00 | V2: 3,466.292000 | W2: 0.00 | X2: 0.00 | Y2: 0.00 | Z2: 0.00 | AA2: 0.00 | AB2: 0.00 | AC2: 44.44 | AD2: 18.15 | AE2: 144.94 | AF2: 0.00 | AG2: 0.00 | AH2: 0.00 | AL2: 27,576,278.58 | AM2: 7,955.56 | AN2: 3,466.292000 | AO2: 0.00 | AP2: 0.00 | AQ2: 0.000000 | AR2: 27,576,278.58 | AS2: 7,955.56 | AT2: 3,466.292000 | AU2: 27,576,278.58 | AV2: 7,955.56 | AW2: 3,466.292000 | AX2: 0.00 | BA2: 551,525.57 | BD2: 27,024,753.01 | BE2: 7,955.56 | BF2: 3,396.966160 | BG2: 3,396.966160
A3: 66302010101 | B3: 4,571,218.80 | C3: 83,200.00 | D3: 54.942534 | E3: 0.00 | F3: 0.00 | G3: 0.000000 | H3: 0.00 | I3: 0.00 | J3: 0.000000 | K3: 0.00 | L3: 0.00 | M3: 0.000000 | N3: 0.00 | O3: 11,400.00 | P3: 0.000000 | Q3: 0.00 | R3: 0.00 | S3: 0.000000 | T3: 4,571,218.80 | U3: 71,800.00 | V3: 63.666000 | W3: 0.00 | X3: 0.00 | Y3: 0.00 | Z3: 109.70 | AA3: 94.27 | AB3: 16.38 | AC3: 2,387.01 | AD3: 1,627.77 | AE3: 46.64 | AF3: 0.00 | AG3: 0.00 | AH3: 0.00 | AL3: 4,412,262.82 | AM3: 69,303.28 | AN3: 63.666000 | AO3: 0.00 | AP3: 0.00 | AQ3: 0.000000 | AR3: 4,412,262.82 | AS3: 69,303.28 | AT3: 63.666000 | AU3: 4,412,262.82 | AV3: 69,303.28 | AW3: 63.666000 | AX3: 331,090.01 | BA3: 88,245.26 | BD3: 3,992,927.55 | BE3: 69,303.28 | BF3: 57.615273 | BG3: 57.615273
A4: 66302010201 | B4: 5,952,771.00 | C4: 43,200.00 | D4: 137.795625 | E4: 0.00 | F4: 0.00 | G4: 0.000000 | H4: 0.00 | I4: 0.00 | J4: 0.000000 | K4: 0.00 | L4: 0.00 | M4: 0.000000 | N4: 0.00 | O4: 5,800.00 | P4: 0.000000 | Q4: 0.00 | R4: 0.00 | S4: 0.000000 | T4: 5,952,771.00 | U4: 37,400.00 | V4: 159.165000 | W4: 0.00 | X4: 0.00 | Y4: 0.00 | Z4: 373.27 | AA4: 333.23 | AB4: 12.01 | AC4: 1,192.65 | AD4: 958.43 | AE4: 24.44 | AF4: 0.00 | AG4: 0.00 | AH4: 0.00 | AL4: 5,703,531.32 | AM4: 35,834.08 | AN4: 159.165000 | AO4: 0.00 | AP4: 0.00 | AQ4: 0.000000 | AR4: 5,703,531.32 | AS4: 35,834.08 | AT4: 159.165000 | AU4: 5,703,531.32 | AV4: 35,834.08 | AW4: 159.165000 | AX4: 435,884.93 | BA4: 114,070.63 | BD4: 5,153,575.76 | BE4: 35,834.08 | BF4: 143.817723 | BG4: 143.817723
A5: 66302010501 | B5: 11,714,544.00 | C5: 43,600.00 | D5: 268.682202 | E5: 0.00 | F5: 0.00 | G5: 0.000000 | H5: 0.00 | I5: 0.00 | J5: 0.000000 | K5: 0.00 | L5: 0.00 | M5: 0.000000 | N5: 0.00 | O5: 6,800.00 | P5: 0.000000 | Q5: 0.00 | R5: 0.00 | S5: 0.000000 | T5: 11,714,544.00 | U5: 36,800.00 | V5: 318.330000 | W5: 0.00 | X5: 0.00 | Y5: 0.00 | Z5: 336.57 | AA5: 251.36 | AB5: 33.90 | AC5: 1,131.93 | AD5: 783.65 | AE5: 44.44 | AF5: 0.00 | AG5: 0.00 | AH5: 0.00 | AL5: 11,247,077.93 | AM5: 35,331.50 | AN5: 318.330000 | AO5: 0.00 | AP5: 0.00 | AQ5: 0.000000 | AR5: 11,247,077.93 | AS5: 35,331.50 | AT5: 318.330000 | AU5: 11,247,077.93 | AV5: 35,331.50 | AW5: 318.330000 | AX5: 822,599.34 | BA5: 224,941.56 | BD5: 10,199,537.03 | BE5: 35,331.50 | BF5: 288.681082 | BG5: 288.681082
A6: 66302011001 | B6: 29,541,024.00 | C6: 53,000.00 | D6: 557.377811 | E6: 0.00 | F6: 0.00 | G6: 0.000000 | H6: 0.00 | I6: 0.00 | J6: 0.000000 | K6: 0.00 | L6: 0.00 | M6: 0.000000 | N6: 0.00 | O6: 6,600.00 | P6: 0.000000 | Q6: 0.00 | R6: 0.00 | S6: 0.000000 | T6: 29,541,024.00 | U6: 46,400.00 | V6: 636.660000 | W6: 0.00 | X6: 0.00 | Y6: 0.00 | Z6: 342.90 | AA6: 308.52 | AB6: 11.14 | AC6: 1,932.00 | AD6: 1,507.70 | AE6: 28.14 | AF6: 0.00 | AG6: 0.00 | AH6: 0.00 | AL6: 28,092,684.33 | AM6: 44,125.10 | AN6: 636.660000 | AO6: 0.00 | AP6: 0.00 | AQ6: 0.000000 | AR6: 28,092,684.33 | AS6: 44,125.10 | AT6: 636.660000 | AU6: 28,092,684.33 | AV6: 44,125.10 | AW6: 636.660000 | AX6: 1,984,872.00 | BA6: 561,853.69 | BD6: 25,545,958.64 | BE6: 44,125.10 | BF6: 578.943964 | BG6: 578.943964
A7: 66302015050 | B7: 471,856.80 | C7: 2,240,000.00 | D7: 0.210650 | E7: 0.00 | F7: 0.00 | G7: 0.000000 | H7: 0.00 | I7: 0.00 | J7: 0.000000 | K7: 0.00 | L7: 0.00 | M7: 0.000000 | N7: 0.00 | O7: 372,000.00 | P7: 0.000000 | Q7: 0.00 | R7: 0.00 | S7: 0.000000 | T7: 471,856.80 | U7: 1,868,000.00 | V7: 0.252600 | W7: 0.00 | X7: 0.00 | Y7: 0.00 | Z7: 3,087.04 | AA7: 990.21 | AB7: 211.75 | AC7: 0.00 | AD7: 0.00 | AE7: 0.00 | AF7: 0.00 | AG7: 0.00 | AH7: 0.00 | AL7: 471,077.01 | AM7: 1,864,912.96 | AN7: 0.252600 | AO7: 0.00 | AP7: 0.00 | AQ7: 0.000000 | AR7: 471,077.01 | AS7: 1,864,912.96 | AT7: 0.252600 | AU7: 471,077.01 | AV7: 1,864,912.96 | AW7: 0.252600 | AX7: 0.00 | BA7: 9,421.54 | BD7: 461,655.47 | BE7: 1,864,912.96 | BF7: 0.247548 | BG7: 0.247548
A8: 66302020601 | B8: 3,731,515.20 | C8: 13,804.00 | D8: 270.321298 | E8: 0.00 | F8: 0.00 | G8: 0.000000 | H8: 0.00 | I8: 0.00 | J8: 0.000000 | K8: 0.00 | L8: 0.00 | M8: 0.000000 | N8: 0.00 | O8: 812.00 | P8: 0.000000 | Q8: 0.00 | R8: 0.00 | S8: 0.000000 | T8: 3,731,515.20 | U8: 12,992.00 | V8: 287.216379 | W8: 0.00 | X8: 0.00 | Y8: 0.00 | Z8: 646.83 | AA8: 777.73 | AC8: 203.29 | AD8: 246.41 | AF8: 0.00 | AG8: 0.00 | AH8: 0.00 | AL8: 3,487,347.78 | AM8: 12,141.88 | AN8: 287.216379 | AO8: 0.00 | AP8: 0.00 | AQ8: 0.000000 | AR8: 3,487,347.78 | AS8: 12,141.88 | AT8: 287.216379 | AU8: 51,563,589.32 | AV8: 198,871.19 | AW8: 259.281342 | AX8: 927,982.70 | BA8: 1,031,271.79 | BD8: 49,604,334.83 | BE8: 198,871.19 | BF8: 249.429465 | BG8: 249.429465
A9: 66302020602 | B9: 51,011,006.00 | C9: 230,608.00 | D9: 221.202239 | E9: 0.00 | F9: 0.00 | G9: 0.000000 | H9: 0.00 | I9: 0.00 | J9: 0.000000 | K9: 0.00 | L9: 0.00 | M9: 0.000000 | N9: 0.00 | O9: 32,480.00 | P9: 0.000000 | Q9: 0.00 | R9: 0.00 | S9: 0.000000 | T9: 51,011,006.00 | U9: 198,128.00 | V9: 257.464901 | W9: 0.00 | X9: 0.00 | Y9: 0.00 | Z9: 8,430.17 | AA9: 7,378.64 | AB9: 14.25 | AC9: 4,089.20 | AD9: 3,244.11 | AE9: 26.05 | AF9: 0.00 | AG9: 0.00 | AH9: 0.00 | AL9: 47,787,707.55 | AM9: 185,608.63 | AN9: 257.464901 | AO9: 0.00 | AP9: 0.00 | AQ9: 0.000000 | AR9: 47,787,707.55 | AS9: 185,608.63 | AT9: 257.464901 | AU9: 51,563,589.32 | AV9: 198,871.19 | AW9: 259.281342 | AX9: 927,982.70 | BA9: 1,031,271.79 | BD9: 49,604,334.83 | BE9: 198,871.19 | BF9: 249.429465 | BG9: 249.429465
A10: 66302020603 | B10: 298,658.00 | C10: 1,160.00 | D10: 257.463793 | E10: 0.00 | F10: 0.00 | G10: 0.000000 | H10: 0.00 | I10: 0.00 | J10: 0.000000 | K10: 0.00 | L10: 0.00 | M10: 0.000000 | N10: 0.00 | O10: 0.00 | P10: 0.000000 | Q10: 0.00 | R10: 0.00 | S10: 0.000000 | T10: 298,658.00 | U10: 1,160.00 | V10: 257.463793 | W10: 0.00 | X10: 0.00 | Y10: 0.00 | Z10: 26.35 | AA10: 58.23 | AC10: 12.97 | AD10: 21.73 | AF10: 0.00 | AG10: 0.00 | AH10: 0.00 | AL10: 288,534.00 | AM10: 1,120.68 | AN10: 257.463793 | AO10: 0.00 | AP10: 0.00 | AQ10: 0.000000 | AR10: 288,534.00 | AS10: 1,120.68 | AT10: 257.463793 | AU10: 51,563,589.32 | AV10: 198,871.19 | AW10: 259.281342 | AX10: 927,982.70 | BA10: 1,031,271.79 | BD10: 49,604,334.83 | BE10: 198,871.19 | BF10: 249.429465 | BG10: 249.429465
A11: 66302020604 | B11: 0.00 | C11: 0.00 | D11: 0.000000 | E11: 0.00 | F11: 0.00 | G11: 0.000000 | H11: 0.00 | I11: 0.00 | J11: 0.000000 | K11: 0.00 | L11: 0.00 | M11: 0.000000 | N11: 0.00 | O11: 0.00 | P11: 0.000000 | Q11: 0.00 | R11: 0.00 | S11: 0.000000 | T11: 0.00 | U11: 0.00 | V11: 0.000000 | W11: 0.00 | X11: 0.00 | Y11: 0.00 | Z11: 0.00 | AA11: 0.00 | AB11: 0.00 | AC11: 0.00 | AD11: 0.00 | AE11: 0.00 | AF11: 0.00 | AG11: 0.00 | AH11: 0.00 | AL11: 0.00 | AM11: 0.00 | AN11: 0.000000 | AO11: 0.00 | AP11: 0.00 | AQ11: 0.000000 | AR11: 0.00 | AS11: 0.00 | AT11: 0.000000 | AU11: 51,563,589.32 | AV11: 198,871.19 | AW11: 259.281342 | AX11: 927,982.70 | BA11: 1,031,271.79 | BD11: 49,604,334.83 | BE11: 198,871.19 | BF11: 249.429465 | BG11: 249.429465
A12: 66302030001 | B12: 149,992.56 | C12: 22,800.00 | D12: 6.578621 | E12: 0.00 | F12: 0.00 | G12: 0.000000 | H12: 149,992.56 | I12: 21,600.00 | J12: 6.944100 | K12: 0.00 | L12: 0.00 | M12: 0.000000 | N12: 0.00 | O12: 1,200.00 | P12: 0.000000 | Q12: 0.00 | R12: 0.00 | S12: 0.000000 | T12: 0.00 | U12: 0.00 | V12: 0.000000 | W12: 0.00 | X12: 0.00 | Y12: 0.00 | Z12: 0.00 | AA12: 0.00 | AB12: 0.00 | AC12: 0.00 | AD12: 0.00 | AE12: 0.00 | AF12: 0.00 | AG12: 0.00 | AH12: 0.00 | AL12: 0.00 | AM12: 0.00 | AN12: 0.000000 | AO12: 0.00 | AP12: 0.00 | AQ12: 0.000000 | AR12: 0.00 | AS12: 0.00 | AT12: 0.000000 | AU12: 0.00 | AV12: 0.00 | AW12: 0.000000 | AX12: 0.00 | BA12: 0.00 | BD12: 0.00 | BE12: 0.00 | BF12: 0.000000 | BG12: 6.944100
A13: 66302030002 | B13: 0.00 | C13: 0.00 | D13: 0.000000 | E13: 0.00 | F13: 0.00 | G13: 0.000000 | H13: 0.00 | I13: 0.00 | J13: 0.000000 | K13: 0.00 | L13: 0.00 | M13: 0.000000 | N13: 0.00 | O13: 0.00 | P13: 0.000000 | Q13: 0.00 | R13: 0.00 | S13: 0.000000 | T13: 0.00 | U13: 0.00 | V13: 0.000000 | W13: 0.00 | X13: 0.00 | Y13: 0.00 | Z13: 0.00 | AA13: 0.00 | AB13: 0.00 | AC13: 0.00 | AD13: 0.00 | AE13: 0.00 | AF13: 0.00 | AG13: 0.00 | AH13: 0.00 | AL13: 0.00 | AM13: 0.00 | AN13: 0.000000 | AO13: 0.00 | AP13: 0.00 | AQ13: 0.000000 | AR13: 0.00 | AS13: 0.00 | AT13: 0.000000 | AU13: 0.00 | AV13: 0.00 | AW13: 0.000000 | AX13: 0.00 | BA13: 0.00 | BD13: 0.00 | BE13: 0.00 | BF13: 0.000000 | BG13: 6.944100
A14: 66302030010 | B14: 0.00 | C14: 0.00 | D14: 0.000000 | E14: 0.00 | F14: 0.00 | G14: 0.000000 | H14: 0.00 | I14: 0.00 | J14: 0.000000 | K14: 0.00 | L14: 0.00 | M14: 0.000000 | N14: 0.00 | O14: 0.00 | P14: 0.000000 | Q14: 0.00 | R14: 0.00 | S14: 0.000000 | T14: 0.00 | U14: 0.00 | V14: 0.000000 | W14: 0.00 | X14: 0.00 | Y14: 0.00 | Z14: 0.00 | AA14: 0.00 | AB14: 0.00 | AC14: 0.00 | AD14: 0.00 | AE14: 0.00 | AF14: 0.00 | AG14: 0.00 | AH14: 0.00 | AL14: 0.00 | AM14: 0.00 | AN14: 0.000000 | AO14: 0.00 | AP14: 0.00 | AQ14: 0.000000 | AR14: 0.00 | AS14: 0.00 | AT14: 0.000000 | AU14: 0.00 | AV14: 0.00 | AW14: 0.000000 | AX14: 0.00 | BA14: 0.00 | BD14: 0.00 | BE14: 0.00 | BF14: 0.000000 | BG14: 6.944100
A15: 66302030201 | B15: 1,733,160.00 | C15: 142,200.00 | D15: 12.188186 | E15: 0.00 | F15: 0.00 | G15: 0.000000 | H15: 1,733,160.00 | I15: 124,800.00 | J15: 13.887500 | K15: 0.00 | L15: 0.00 | M15: 0.000000 | N15: 0.00 | O15: 17,400.00 | P15: 0.000000 | Q15: 0.00 | R15: 0.00 | S15: 0.000000 | T15: 0.00 | U15: 0.00 | V15: 0.000000 | W15: 0.00 | X15: 0.00 | Y15: 0.00 | Z15: 0.00 | AA15: 0.00 | AB15: 0.00 | AC15: 0.00 | AD15: 0.00 | AE15: 0.00 | AF15: 0.00 | AG15: 0.00 | AH15: 0.00 | AL15: 0.00 | AM15: 0.00 | AN15: 0.000000 | AO15: 0.00 | AP15: 0.00 | AQ15: 0.000000 | AR15: 0.00 | AS15: 0.00 | AT15: 0.000000 | AU15: 0.00 | AV15: 0.00 | AW15: 0.000000 | AX15: 0.00 | BA15: 0.00 | BD15: 0.00 | BE15: 0.00 | BF15: 0.000000 | BG15: 13.887500
A16: 66302030202 | B16: 0.00 | C16: 0.00 | D16: 0.000000 | E16: 0.00 | F16: 0.00 | G16: 0.000000 | H16: 0.00 | I16: 0.00 | J16: 0.000000 | K16: 0.00 | L16: 0.00 | M16: 0.000000 | N16: 0.00 | O16: 0.00 | P16: 0.000000 | Q16: 0.00 | R16: 0.00 | S16: 0.000000 | T16: 0.00 | U16: 0.00 | V16: 0.000000 | W16: 0.00 | X16: 0.00 | Y16: 0.00 | Z16: 0.00 | AA16: 0.00 | AB16: 0.00 | AC16: 0.00 | AD16: 0.00 | AE16: 0.00 | AF16: 0.00 | AG16: 0.00 | AH16: 0.00 | AL16: 0.00 | AM16: 0.00 | AN16: 0.000000 | AO16: 0.00 | AP16: 0.00 | AQ16: 0.000000 | AR16: 0.00 | AS16: 0.00 | AT16: 0.000000 | AU16: 0.00 | AV16: 0.00 | AW16: 0.000000 | AX16: 0.00 | BA16: 0.00 | BD16: 0.00 | BE16: 0.00 | BF16: 0.000000 | BG16: 13.887500
A17: 66302030210 | B17: 0.00 | C17: 0.00 | D17: 0.000000 | E17: 0.00 | F17: 0.00 | G17: 0.000000 | H17: 0.00 | I17: 0.00 | J17: 0.000000 | K17: 0.00 | L17: 0.00 | M17: 0.000000 | N17: 0.00 | O17: 0.00 | P17: 0.000000 | Q17: 0.00 | R17: 0.00 | S17: 0.000000 | T17: 0.00 | U17: 0.00 | V17: 0.000000 | W17: 0.00 | X17: 0.00 | Y17: 0.00 | Z17: 0.00 | AA17: 0.00 | AB17: 0.00 | AC17: 0.00 | AD17: 0.00 | AE17: 0.00 | AF17: 0.00 | AG17: 0.00 | AH17: 0.00 | AL17: 0.00 | AM17: 0.00 | AN17: 0.000000 | AO17: 0.00 | AP17: 0.00 | AQ17: 0.000000 | AR17: 0.00 | AS17: 0.00 | AT17: 0.000000 | AU17: 0.00 | AV17: 0.00 | AW17: 0.000000 | AX17: 0.00 | BA17: 0.00 | BD17: 0.00 | BE17: 0.00 | BF17: 0.000000 | BG17: 13.887500
A18: 66302031001 | B18: 9,332,618.40 | C18: 184,800.00 | D18: 50.501182 | E18: 0.00 | F18: 0.00 | G18: 0.000000 | H18: 9,332,618.40 | I18: 168,000.00 | J18: 55.551300 | K18: 0.00 | L18: 0.00 | M18: 0.000000 | N18: 0.00 | O18: 16,800.00 | P18: 0.000000 | Q18: 0.00 | R18: 0.00 | S18: 0.000000 | T18: 0.00 | U18: 0.00 | V18: 0.000000 | W18: 0.00 | X18: 0.00 | Y18: 0.00 | Z18: 0.00 | AA18: 0.00 | AB18: 0.00 | AC18: 0.00 | AD18: 0.00 | AE18: 0.00 | AF18: 0.00 | AG18: 0.00 | AH18: 0.00 | AL18: 0.00 | AM18: 0.00 | AN18: 0.000000 | AO18: 0.00 | AP18: 0.00 | AQ18: 0.000000 | AR18: 0.00 | AS18: 0.00 | AT18: 0.000000 | AU18: 0.00 | AV18: 0.00 | AW18: 0.000000 | AX18: 0.00 | BA18: 0.00 | BD18: 0.00 | BE18: 0.00 | BF18: 0.000000 | BG18: 55.551300
A19: 66302031002 | B19: 0.00 | C19: 0.00 | D19: 0.000000 | E19: 0.00 | F19: 0.00 | G19: 0.000000 | H19: 0.00 | I19: 0.00 | J19: 0.000000 | K19: 0.00 | L19: 0.00 | M19: 0.000000 | N19: 0.00 | O19: 0.00 | P19: 0.000000 | Q19: 0.00 | R19: 0.00 | S19: 0.000000 | T19: 0.00 | U19: 0.00 | V19: 0.000000 | W19: 0.00 | X19: 0.00 | Y19: 0.00 | Z19: 0.00 | AA19: 0.00 | AB19: 0.00 | AC19: 0.00 | AD19: 0.00 | AE19: 0.00 | AF19: 0.00 | AG19: 0.00 | AH19: 0.00 | AL19: 0.00 | AM19: 0.00 | AN19: 0.000000 | AO19: 0.00 | AP19: 0.00 | AQ19: 0.000000 | AR19: 0.00 | AS19: 0.00 | AT19: 0.000000 | AU19: 0.00 | AV19: 0.00 | AW19: 0.000000 | AX19: 0.00 | BA19: 0.00 | BD19: 0.00 | BE19: 0.00 | BF19: 0.000000 | BG19: 55.551300
A20: 66302031010 | B20: 0.00 | C20: 0.00 | D20: 0.000000 | E20: 0.00 | F20: 0.00 | G20: 0.000000 | H20: 0.00 | I20: 0.00 | J20: 0.000000 | K20: 0.00 | L20: 0.00 | M20: 0.000000 | N20: 0.00 | O20: 0.00 | P20: 0.000000 | Q20: 0.00 | R20: 0.00 | S20: 0.000000 | T20: 0.00 | U20: 0.00 | V20: 0.000000 | W20: 0.00 | X20: 0.00 | Y20: 0.00 | Z20: 0.00 | AA20: 0.00 | AB20: 0.00 | AC20: 0.00 | AD20: 0.00 | AE20: 0.00 | AF20: 0.00 | AG20: 0.00 | AH20: 0.00 | AL20: 0.00 | AM20: 0.00 | AN20: 0.000000 | AO20: 0.00 | AP20: 0.00 | AQ20: 0.000000 | AR20: 0.00 | AS20: 0.00 | AT20: 0.000000 | AU20: 0.00 | AV20: 0.00 | AW20: 0.000000 | AX20: 0.00 | BA20: 0.00 | BD20: 0.00 | BE20: 0.00 | BF20: 0.000000 | BG20: 55.551300
A21: 66302032501 | B21: 9,499,296.24 | C21: 73,500.00 | D21: 129.242126 | E21: 0.00 | F21: 0.00 | G21: 0.000000 | H21: 9,499,296.24 | I21: 68,400.00 | J21: 138.878600 | K21: 0.00 | L21: 0.00 | M21: 0.000000 | N21: 0.00 | O21: 5,100.00 | P21: 0.000000 | Q21: 0.00 | R21: 0.00 | S21: 0.000000 | T21: 0.00 | U21: 0.00 | V21: 0.000000 | W21: 0.00 | X21: 0.00 | Y21: 0.00 | Z21: 0.00 | AA21: 0.00 | AB21: 0.00 | AC21: 0.00 | AD21: 0.00 | AE21: 0.00 | AF21: 0.00 | AG21: 0.00 | AH21: 0.00 | AL21: 0.00 | AM21: 0.00 | AN21: 0.000000 | AO21: 0.00 | AP21: 0.00 | AQ21: 0.000000 | AR21: 0.00 | AS21: 0.00 | AT21: 0.000000 | AU21: 0.00 | AV21: 0.00 | AW21: 0.000000 | AX21: 0.00 | BA21: 0.00 | BD21: 0.00 | BE21: 0.00 | BF21: 0.000000 | BG21: 138.878600
A22: 66302032502 | B22: 0.00 | C22: 0.00 | D22: 0.000000 | E22: 0.00 | F22: 0.00 | G22: 0.000000 | H22: 0.00 | I22: 0.00 | J22: 0.000000 | K22: 0.00 | L22: 0.00 | M22: 0.000000 | N22: 0.00 | O22: 0.00 | P22: 0.000000 | Q22: 0.00 | R22: 0.00 | S22: 0.000000 | T22: 0.00 | U22: 0.00 | V22: 0.000000 | W22: 0.00 | X22: 0.00 | Y22: 0.00 | Z22: 0.00 | AA22: 0.00 | AB22: 0.00 | AC22: 0.00 | AD22: 0.00 | AE22: 0.00 | AF22: 0.00 | AG22: 0.00 | AH22: 0.00 | AL22: 0.00 | AM22: 0.00 | AN22: 0.000000 | AO22: 0.00 | AP22: 0.00 | AQ22: 0.000000 | AR22: 0.00 | AS22: 0.00 | AT22: 0.000000 | AU22: 0.00 | AV22: 0.00 | AW22: 0.000000 | AX22: 0.00 | BA22: 0.00 | BD22: 0.00 | BE22: 0.00 | BF22: 0.000000 | BG22: 138.878600
... A41: 66302036384 | B41: 0.00 | C41: 0.00 | D41: 0.000000 | E41: 0.00 | F41: 0.00 | G41: 0.000000 | H41: 0.00 | I41: 0.00 | J41: 0.000000 | K41: 0.00 | L41: 0.00 | M41: 0.000000 | N41: 0.00 | O41: 0.00 | P41: 0.000000 | Q41: 0.00 | R41: 0.00 | S41: 0.000000 | T41: 0.00 | U41: 0.00 | V41: 0.000000 | W41: 0.00 | X41: 0.00 | Y41: 0.00 | Z41: 0.00 | AA41: 0.00 | AB41: 0.00 | AC41: 0.00 | AD41: 0.00 | AE41: 0.00 | AF41: 0.00 | AG41: 0.00 | AH41: 0.00 | AL41: 0.00 | AM41: 0.00 | AN41: 0.000000 | AO41: 0.00 | AP41: 0.00 | AQ41: 0.000000 | AR41: 0.00 | AS41: 0.00 | AT41: 0.000000 | AU41: 0.00 | AV41: 0.00 | AW41: 0.000000 | AX41: 0.00 | BA41: 0.00 | BD41: 0.00 | BE41: 0.00 | BF41: 0.000000 | BG41: 6,124.940000
A42: 66302046760 | B42: 4,441,050.00 | C42: 84,120.00 | D42: 52.794223 | E42: 0.00 | F42: 0.00 | G42: 0.000000 | H42: 0.00 | I42: 0.00 | J42: 0.000000 | K42: 0.00 | L42: 0.00 | M42: 0.000000 | N42: 0.00 | O42: 20,220.00 | P42: 0.000000 | Q42: 0.00 | R42: 0.00 | S42: 0.000000 | T42: 4,441,050.00 | U42: 63,900.00 | V42: 69.500000 | W42: 0.00 | X42: 0.00 | Y42: 0.00 | Z42: 16,951.69 | AA42: 17,925.23 | AC42: 31.05 | AD42: 20.54 | AE42: 51.16 | AF42: 0.00 | AG42: 0.00 | AH42: 0.00 | AL42: 3,260,749.89 | AM42: 46,917.26 | AN42: 69.500000 | AO42: 0.00 | AP42: 0.00 | AQ42: 0.000000 | AR42: 3,260,749.89 | AS42: 46,917.26 | AT42: 69.500000 | AU42: 3,260,749.89 | AV42: 46,917.26 | AW42: 69.500000 | AX42: 0.00 | BA42: 0.00 | BD42: 3,260,749.89 | BE42: 46,917.26 | BF42: 69.500000 | BG42: 69.500000
A43: 66302060002 | B43: 0.00 | C43: 0.00 | D43: 0.000000 | E43: 0.00 | F43: 0.00 | G43: 0.000000 | H43: 0.00 | I43: 0.00 | J43: 0.000000 | K43: 0.00 | L43: 0.00 | M43: 0.000000 | N43: 0.00 | O43: 0.00 | P43: 0.000000 | Q43: 0.00 | R43: 0.00 | S43: 0.000000 | T43: 0.00 | U43: 0.00 | V43: 0.000000 | W43: 0.00 | X43: 0.00 | Y43: 0.00 | Z43: 0.00 | AA43: 0.00 | AB43: 0.00 | AC43: 0.00 | AD43: 0.00 | AE43: 0.00 | AF43: 0.00 | AG43: 0.00 | AH43: 0.00 | AL43: 0.00 | AM43: 0.00 | AN43: 0.000000 | AO43: 0.00 | AP43: 0.00 | AQ43: 0.000000 | AR43: 0.00 | AS43: 0.00 | AT43: 0.000000 | AU43: 0.00 | AV43: 0.00 | AW43: 0.000000 | AX43: 0.00 | BA43: 0.00 | BD43: 0.00 | BE43: 0.00 | BF43: 0.000000 | BG43: 20,487.968200
A44: 66302061002 | B44: 9,202,028.00 | C44: 420.00 | D44: 21,909.590476 | E44: 0.00 | F44: 0.00 | G44: 0.000000 | H44: 0.00 | I44: 0.00 | J44: 0.000000 | K44: 0.00 | L44: 0.00 | M44: 0.000000 | N44: 0.00 | O44: 20.00 | P44: 0.000000 | Q44: 0.00 | R44: 0.00 | S44: 0.000000 | T44: 9,202,028.00 | U44: 400.00 | V44: 23,005.070000 | W44: 0.00 | X44: 0.00 | Y44: 0.00 | Z44: 79.23 | AA44: 24.88 | AB44: 218.45 | AC44: 10.58 | AD44: 7.59 | AE44: 39.37 | AF44: 0.00 | AG44: 0.00 | AH44: 0.00 | AL44: 7,135,995.75 | AM44: 310.19 | AN44: 23,005.070000 | AO44: 0.00 | AP44: 0.00 | AQ44: 0.000000 | AR44: 7,135,995.75 | AS44: 310.19 | AT44: 23,005.070000 | AU44: 7,135,995.75 | AV44: 310.19 | AW44: 23,005.070000 | AX44: 179,022.13 | BA44: 142,719.92 | BD44: 6,814,253.71 | BE44: 310.19 | BF44: 21,967.835895 | BG44: 21,967.835895
A45: 66302061601 | B45: 0.00 | C45: 0.00 | D45: 0.000000 | E45: 0.00 | F45: 0.00 | G45: 0.000000 | H45: 0.00 | I45: 0.00 | J45: 0.000000 | K45: 0.00 | L45: 0.00 | M45: 0.000000 | N45: 0.00 | O45: 0.00 | P45: 0.000000 | Q45: 0.00 | R45: 0.00 | S45: 0.000000 | T45: 0.00 | U45: 0.00 | V45: 0.000000 | W45: 0.00 | X45: 0.00 | Y45: 0.00 | Z45: 0.00 | AA45: 0.00 | AB45: 0.00 | AC45: 0.00 | AD45: 0.00 | AE45: 0.00 | AF45: 0.00 | AG45: 0.00 | AH45: 0.00 | AL45: 0.00 | AM45: 0.00 | AN45: 0.000000 | AO45: 0.00 | AP45: 0.00 | AQ45: 0.000000 | AR45: 0.00 | AS45: 0.00 | AT45: 0.000000 | AU45: 7,468,659.88 | AV45: 324.65 | AW45: 23,005.070000 | AX45: 156,977.95 | BA45: 149,373.20 | BD45: 7,162,308.73 | BE45: 324.65 | BF45: 22,061.442930 | BG45: 22,061.442929
A46: 66302061603 | B46: 7,821,723.80 | C46: 400.00 | D46: 19,554.309500 | E46: 0.00 | F46: 0.00 | G46: 0.000000 | H46: 0.00 | I46: 0.00 | J46: 0.000000 | K46: 0.00 | L46: 0.00 | M46: 0.000000 | N46: 0.00 | O46: 60.00 | P46: 0.000000 | Q46: 0.00 | R46: 0.00 | S46: 0.000000 | T46: 7,821,723.80 | U46: 340.00 | V46: 23,005.070000 | W46: 0.00 | X46: 0.00 | Y46: 0.00 | Z46: 3.78 | AA46: 3.19 | AB46: 18.44 | AC46: 11.57 | AD46: 8.31 | AE46: 39.19 | AF46: 0.00 | AG46: 0.00 | AH46: 0.00 | AL46: 7,468,659.88 | AM46: 324.65 | AN46: 23,005.070000 | AO46: 0.00 | AP46: 0.00 | AQ46: 0.000000 | AR46: 7,468,659.88 | AS46: 324.65 | AT46: 23,005.070000 | AU46: 7,468,659.88 | AV46: 324.65 | AW46: 23,005.070000 | AX46: 156,977.95 | BA46: 149,373.20 | BD46: 7,162,308.73 | BE46: 324.65 | BF46: 22,061.442930 | BG46: 22,061.442929
A47: 66302063201 | B47: 0.00 | C47: 0.00 | D47: 0.000000 | E47: 0.00 | F47: 0.00 | G47: 0.000000 | H47: 0.00 | I47: 0.00 | J47: 0.000000 | K47: 0.00 | L47: 0.00 | M47: 0.000000 | N47: 0.00 | O47: 0.00 | P47: 0.000000 | Q47: 0.00 | R47: 0.00 | S47: 0.000000 | T47: 0.00 | U47: 0.00 | V47: 0.000000 | W47: 0.00 | X47: 0.00 | Y47: 0.00 | Z47: 0.00 | AA47: 0.00 | AB47: 0.00 | AC47: 0.00 | AD47: 0.00 | AE47: 0.00 | AF47: 0.00 | AG47: 0.00 | AH47: 0.00 | AL47: 0.00 | AM47: 0.00 | AN47: 0.000000 | AO47: 0.00 | AP47: 0.00 | AQ47: 0.000000 | AR47: 0.00 | AS47: 0.00 | AT47: 0.000000 | AU47: 9,806,692.53 | AV47: 426.28 | AW47: 23,005.070000 | AX47: 251,584.67 | BA47: 196,133.85 | BD47: 9,358,974.02 | BE47: 426.28 | BF47: 21,954.787671 | BG47: 21,954.787671
A48: 66302063203 | B48: 14,033,092.70 | C48: 690.00 | D48: 20,337.815507 | E48: 0.00 | F48: 0.00 | G48: 0.000000 | H48: 0.00 | I48: 0.00 | J48: 0.000000 | K48: 0.00 | L48: 0.00 | M48: 0.000000 | N48: 0.00 | O48: 80.00 | P48: 0.000000 | Q48: 0.00 | R48: 0.00 | S48: 0.000000 | T48: 14,033,092.70 | U48: 610.00 | V48: 23,005.070000 | W48: 0.00 | X48: 0.00 | Y48: 0.00 | Z48: 152.52 | AA48: 117.11 | AB48: 30.24 | AC48: 31.19 | AD48: 21.45 | AE48: 45.41 | AF48: 0.00 | AG48: 0.00 | AH48: 0.00 | AL48: 9,806,692.53 | AM48: 426.28 | AN48: 23,005.070000 | AO48: 0.00 | AP48: 0.00 | AQ48: 0.000000 | AR48: 9,806,692.53 | AS48: 426.28 | AT48: 23,005.070000 | AU48: 9,806,692.53 | AV48: 426.28 | AW48: 23,005.070000 | AX48: 251,584.67 | BA48: 196,133.85 | BD48: 9,358,974.02 | BE48: 426.28 | BF48: 21,954.787671 | BG48: 21,954.787671
A49: 66302064801 | B49: 0.00 | C49: 0.00 | D49: 0.000000 | E49: 0.00 | F49: 0.00 | G49: 0.000000 | H49: 0.00 | I49: 0.00 | J49: 0.000000 | K49: 0.00 | L49: 0.00 | M49: 0.000000 | N49: 0.00 | O49: 0.00 | P49: 0.000000 | Q49: 0.00 | R49: 0.00 | S49: 0.000000 | T49: 0.00 | U49: 0.00 | V49: 0.000000 | W49: 0.00 | X49: 0.00 | Y49: 0.00 | Z49: 0.00 | AA49: 0.00 | AB49: 0.00 | AC49: 0.00 | AD49: 0.00 | AE49: 0.00 | AF49: 0.00 | AG49: 0.00 | AH49: 0.00 | AL49: 0.00 | AM49: 0.00 | AN49: 0.000000 | AO49: 0.00 | AP49: 0.00 | AQ49: 0.000000 | AR49: 0.00 | AS49: 0.00 | AT49: 0.000000 | AU49: 17,480,252.24 | AV49: 759.84 | AW49: 23,005.070000 | AX49: 474,644.22 | BA49: 349,605.04 | BD49: 16,656,002.98 | BE49: 759.84 | BF49: 21,920.308081 | BG49: 21,920.308081
A50: 66302064803 | B50: 27,376,033.30 | C50: 1,370.00 | D50: 19,982.506058 | E50: 0.00 | F50: 0.00 | G50: 0.000000 | H50: 0.00 | I50: 0.00 | J50: 0.000000 | K50: 0.00 | L50: 0.00 | M50: 0.000000 | N50: 0.00 | O50: 180.00 | P50: 0.000000 | Q50: 0.00 | R50: 0.00 | S50: 0.000000 | T50: 27,376,033.30 | U50: 1,190.00 | V50: 23,005.070000 | W50: 0.00 | X50: 0.00 | Y50: 0.00 | Z50: 380.36 | AA50: 370.44 | AB50: 2.68 | AC50: 49.80 | AD50: 39.84 | AE50: 24.99 | AF50: 0.00 | AG50: 0.00 | AH50: 0.00 | AL50: 17,480,252.24 | AM50: 759.84 | AN50: 23,005.070000 | AO50: 0.00 | AP50: 0.00 | AQ50: 0.000000 | AR50: 17,480,252.24 | AS50: 759.84 | AT50: 23,005.070000 | AU50: 17,480,252.24 | AV50: 759.84 | AW50: 23,005.070000 | AX50: 474,644.22 | BA50: 349,605.04 | BD50: 16,656,002.98 | BE50: 759.84 | BF50: 21,920.308081 | BG50: 21,920.308081
A51: 66302066401 | B51: 0.00 | C51: 0.00 | D51: 0.000000 | E51: 0.00 | F51: 0.00 | G51: 0.000000 | H51: 0.00 | I51: 0.00 | J51: 0.000000 | K51: 0.00 | L51: 0.00 | M51: 0.000000 | N51: 0.00 | O51: 0.00 | P51: 0.000000 | Q51: 0.00 | R51: 0.00 | S51: 0.000000 | T51: 0.00 | U51: 0.00 | V51: 0.000000 | W51: 0.00 | X51: 0.00 | Y51: 0.00 | Z51: 0.00 | AA51: 0.00 | AB51: 0.00 | AC51: 0.00 | AD51: 0.00 | AE51: 0.00 | AF51: 0.00 | AG51: 0.00 | AH51: 0.00 | AL51: 0.00 | AM51: 0.00 | AN51: 0.000000 | AO51: 0.00 | AP51: 0.00 | AQ51: 0.000000 | AR51: 0.00 | AS51: 0.00 | AT51: 0.000000 | AU51: 52,073,533.10 | AV51: 2,263.57 | AW51: 23,005.070000 | AX51: 1,265,510.56 | BA51: 1,041,470.66 | BD51: 49,766,551.88 | BE51: 2,263.57 | BF51: 21,985.890747 | BG51: 21,985.890747
A52: 66302066403 | B52: 57,742,725.70 | C52: 2,910.00 | D52: 19,842.861065 | E52: 0.00 | F52: 0.00 | G52: 0.000000 | H52: 0.00 | I52: 0.00 | J52: 0.000000 | K52: 0.00 | L52: 0.00 | M52: 0.000000 | N52: 0.00 | O52: 400.00 | P52: 0.000000 | Q52: 0.00 | R52: 0.00 | S52: 0.000000 | T52: 57,742,725.70 | U52: 2,510.00 | V52: 23,005.070000 | W52: 0.00 | X52: 0.00 | Y52: 0.00 | Z52: 177.69 | AA52: 74.07 | AB52: 139.89 | AC52: 68.74 | AD52: 51.45 | AE52: 33.60 | AF52: 0.00 | AG52: 0.00 | AH52: 0.00 | AL52: 52,073,533.10 | AM52: 2,263.57 | AN52: 23,005.070000 | AO52: 0.00 | AP52: 0.00 | AQ52: 0.000000 | AR52: 52,073,533.10 | AS52: 2,263.57 | AT52: 23,005.070000 | AU52: 52,073,533.10 | AV52: 2,263.57 | AW52: 23,005.070000 | AX52: 1,265,510.56 | BA52: 1,041,470.66 | BD52: 49,766,551.88 | BE52: 2,263.57 | BF52: 21,985.890747 | BG52: 21,985.890747
A53: 66302071604 | B53: 65,771.40 | C53: 20.00 | D53: 3,288.570000 | E53: 0.00 | F53: 0.00 | G53: 0.000000 | H53: 0.00 | I53: 0.00 | J53: 0.000000 | K53: 0.00 | L53: 0.00 | M53: 0.000000 | N53: 0.00 | O53: 0.00 | P53: 0.000000 | Q53: 0.00 | R53: 0.00 | S53: 0.000000 | T53: 65,771.40 | U53: 20.00 | V53: 3,288.570000 | W53: 0.00 | X53: 0.00 | Y53: 0.00 | Z53: 0.00 | AA53: 0.00 | AB53: 0.00 | AC53: 0.00 | AD53: 0.00 | AE53: 0.00 | AF53: 0.00 | AG53: 0.00 | AH53: 0.00 | AL53: 65,771.40 | AM53: 20.00 | AN53: 3,288.570000 | AO53: 0.00 | AP53: 0.00 | AQ53: 0.000000 | AR53: 65,771.40 | AS53: 20.00 | AT53: 3,288.570000 | AU53: 65,771.40 | AV53: 20.00 | AW53: 3,288.570000 | AX53: 167.72 | BA53: 1,315.43 | BD53: 64,288.25 | BE53: 20.00 | BF53: 3,214.412747 | BG53: 3,214.412746
A54: 66302073204 | B54: 65,771.40 | C54: 20.00 | D54: 3,288.570000 | E54: 0.00 | F54: 0.00 | G54: 0.000000 | H54: 0.00 | I54: 0.00 | J54: 0.000000 | K54: 0.00 | L54: 0.00 | M54: 0.000000 | N54: 0.00 | O54: 0.00 | P54: 0.000000 | Q54: 0.00 | R54: 0.00 | S54: 0.000000 | T54: 65,771.40 | U54: 20.00 | V54: 3,288.570000 | W54: 0.00 | X54: 0.00 | Y54: 0.00 | Z54: 0.00 | AA54: 0.00 | AB54: 0.00 | AC54: 0.00 | AD54: 0.00 | AE54: 0.00 | AF54: 0.00 | AG54: 0.00 | AH54: 0.00 | AL54: 65,771.40 | AM54: 20.00 | AN54: 3,288.570000 | AO54: 0.00 | AP54: 0.00 | AQ54: 0.000000 | AR54: 65,771.40 | AS54: 20.00 | AT54: 3,288.570000 | AU54: 65,771.40 | AV54: 20.00 | AW54: 3,288.570000 | AX54: 0.00 | BA54: 1,315.43 | BD54: 64,455.97 | BE54: 20.00 | BF54: 3,222.798600 | BG54: 3,222.798600
... A56: 66302076404 | B56: 65,771.40 | C56: 20.00 | D56: 3,288.570000 | E56: 0.00 | F56: 0.00 | G56: 0.000000 | H56: 0.00 | I56: 0.00 | J56: 0.000000 | K56: 0.00 | L56: 0.00 | M56: 0.000000 | N56: 0.00 | O56: 0.00 | P56: 0.000000 | Q56: 0.00 | R56: 0.00 | S56: 0.000000 | T56: 65,771.40 | U56: 20.00 | V56: 3,288.570000 | W56: 0.00 | X56: 0.00 | Y56: 0.00 | Z56: 0.00 | AA56: 0.00 | AB56: 0.00 | AC56: 0.00 | AD56: 0.00 | AE56: 0.00 | AF56: 0.00 | AG56: 0.00 | AH56: 0.00 | AL56: 65,771.40 | AM56: 20.00 | AN56: 3,288.570000 | AO56: 0.00 | AP56: 0.00 | AQ56: 0.000000 | AR56: 65,771.40 | AS56: 20.00 | AT56: 3,288.570000 | AU56: 65,771.40 | AV56: 20.00 | AW56: 3,288.570000 | AX56: 69.88 | BA56: 1,315.43 | BD56: 64,386.09 | BE56: 20.00 | BF56: 3,219.304494 | BG56: 3,219.304494

Sheet United Smoothed Indirect Inelig
A1: NDC11 | B1: 12-Month Total Ineligible Cot | C1: 12-Month Total Ineligible State | D1: 12-Month Total Ineligible Contract | E1: 12-Month Total Mail Order Qty | F1: 12-Month Total Net Eligible Qty | G1: Smoothing Ratio COT | H1: Smoothing Ratio State | I1: Smoothing Ratio Contract | J1: Smoothing Ratio Mail Order | K1: Cur. Month Net Eligible Sales Qty | L1: Smoothed Indirect Ineligible Qty COT | M1: Smoothed Indirect Ineligible Qty STATE | N1: Smoothed Indirect Ineligible Qty CONTRACT | O1: Smoothed Indirect Ineligible Qty MAIL ORDER | P1: Cur. Avg Direct Price | Q1: Smoothed Indirect $
A2: 66302001401 | B2: 0 | C2: 0 | D2: 350 | E2: 0 | F2: 63000 | G2: 0.000000% | H2: 0.000000% | I2: 0.555556% | J2: 0.000000% | K2: 8000 | L2: 0 | M2: 0 | N2: 44.44 | O2: 0 | P2: 3466.29 | Q2: 154057.42
A3: 66302010101 | B3: 1160 | C3: 0 | D3: 25240 | E3: 0 | F3: 759205 | G3: 0.152791% | H3: 0.000000% | I3: 3.324530% | J3: 0.000000% | K3: 71800 | L3: 109.7 | M3: 0 | N3: 2387.01 | O3: 0 | P3: 63.67 | Q3: 158955.98
A4: 66302010201 | B4: 4100 | C4: 0 | D4: 13100 | E4: 0 | F4: 410800 | G4: 0.998053% | H4: 0.000000% | I4: 3.188900% | J4: 0.000000% | K4: 37400 | L4: 373.27 | M4: 0 | N4: 1192.65 | O4: 0 | P4: 159.17 | Q4: 249239.68
A5: 66302010501 | B5: 3580 | C5: 0 | D5: 12040 | E5: 0 | F5: 391432 | G5: 0.914591% | H5: 0.000000% | I5: 3.075885% | J5: 0.000000% | K5: 36800 | L5: 336.57 | M5: 0 | N5: 1131.93 | O5: 0 | P5: 318.33 | Q5: 467466.07
A6: 66302011001 | B6: 3677.5 | C6: 0 | D6: 20720 | E6: 0 | F6: 497623 | G6: 0.739013% | H6: 0.000000% | I6: 4.163795% | J6: 0.000000% | K6: 46400 | L6: 342.9 | M6: 0 | N6: 1932 | O6: 0 | P6: 636.66 | Q6: 1448339.7
A7: 66302011006 | B7: 3626.23 | C7: 0 | D7: 10192.49 | E7: 0 | F7: 410291.63 | G7: 0.914591% | H7: 0.000000% | I7: 3.075885% | J7: 0.000000% | K7: 35043.88 | L7: 349.07 | M7: 0 | N7: 1145.74 | O7: 0 | P7: 363.25 | Q7: 441698.92
A8: 66302011007 | B8: 3482.89 | C8: 0 | D8: 10795.37 | E8: 0 | F8: 315651.84 | G8: 0.914591% | H8: 0.000000% | I8: 3.075885% | J8: 0.000000% | K8: 31861.22 | L8: 315.09 | M8: 0 | N8: 1035.51 | O8: 0 | P8: 334.13 | Q8: 509952.19
A9: 66302011008 | B9: 1255 | C9: 0 | D9: 24254.57 | E9: 0 | F9: 835341.26 | G9: 0.152791% | H9: 0.000000% | I9: 3.324530% | J9: 0.000000% | K9: 71185.98 | L9: 96.79 | M9: 0 | N9: 1931.53 | O9: 0 | P9: 71.04 | Q9: 140266.15
A10: 66302011009 | B10: 971.63 | C10: 0 | D10: 22550.03 | E10: 0 | F10: 813172.4 | G10: 0.152791% | H10: 0.000000% | I10: 3.324530% | J10: 0.000000% | K10: 73195.18 | L10: 90.3 | M10: 0 | N10: 1922.71 | O10: 0 | P10: 70.97 | Q10: 168018.57
A11: 66302011010 | B11: 3610.85 | C11: 0 | D11: 10450.11 | E11: 0 | F11: 396404.34 | G11: 0.914591% | H11: 0.000000% | I11: 3.075885% | J11: 0.000000% | K11: 34653.31 | L11: 298.82 | M11: 0 | N11: 1321.07 | O11: 0 | P11: 349.74 | Q11: 448820.18
A12: 66302011011 | B12: 0 | C12: 0 | D12: 339.34 | E12: 0 | F12: 65979.56 | G12: 0.000000% | H12: 0.000000% | I12: 0.555556% | J12: 0.000000% | K12: 6758.81 | L12: 0 | M12: 0 | N12: 46.74 | O12: 0 | P12: 3039.14 | Q12: 141368.16
A13: 66302011012 | B13: 4113.99 | C13: 0 | D13: 12696.4 | E13: 0 | F13: 410420.5 | G13: 0.914591% | H13: 0.000000% | I13: 3.075885% | J13: 0.000000% | K13: 32582.81 | L13: 286.39 | M13: 0 | N13: 1347 | O13: 0 | P13: 367.27 | Q13: 382101.28
... A57: 66302011056 | B57: 4044.22 | C57: 0 | D57: 20012.08 | E57: 0 | F57: 433267.63 | G57: 0.739013% | H57: 0.000000% | I57: 4.163795% | J57: 0.000000% | K57: 47061.77 | L57: 361.36 | M57: 0 | N57: 2313.37 | O57: 0 | P57: 602.14 | Q57: 1227333.2

Sheet United_Smoothed Price Concessio
A1: NDC11 | B1: 12-Month Total Non-Prorated Eligible Rebates | C1: 12-Month Total Prorated Eligible Rebates | D1: 12-Month Total Eligible Chargeback | E1: 12-Month Total Eligible Rebate | F1: 12-Month Total Eligible Prorated Price Appreciation Credit $ | G1: 12-Month Total Total Price Concession | H1: 12-Month Total Non-Smoothed AMP Eligible | I1: Smoothing Ratio | J1: x Current Month Adjusted AMP Eligible Sales $ | K1: Smoothed Eligible Price Concessions $
A2: 66302001401 | B2: $0.00 | C2: $0.00 | D2: $0.00 | E2: $0.00 | F2: $0.00 | G2: $0.00 | H2: $210,762,068.80 | I2: 0.000000% | J2: $27,576,278.58 | K2: $0.00
A3: 66302010101 | B3: $0.00 | C3: $3,500,908.00 | D3: $0.00 | E3: $0.00 | F3: $0.00 | G3: $3,500,908.00 | H3: $46,654,763.96 | I3: 7.503860% | J3: $4,412,262.82 | K3: $331,090.01
A4: 66302010201 | B4: $0.00 | C4: $4,787,741.43 | D4: $0.00 | E4: $0.00 | F4: $0.00 | G4: $4,787,741.43 | H4: $62,647,343.99 | I4: 7.642369% | J4: $5,703,531.32 | K4: $435,884.93
A5: 66302010501 | B5: $0.00 | C5: $8,749,774.60 | D5: $0.00 | E5: $0.00 | F5: $0.00 | G5: $8,749,774.60 | H5: $119,632,233.96 | I5: 7.313894% | J5: $11,247,077.93 | K5: $822,599.34
A6: 66302011001 | B6: $0.00 | C6: $21,287,024.94 | D6: $0.00 | E6: $0.00 | F6: $0.00 | G6: $21,287,024.94 | H6: $301,283,746.83 | I6: 7.065441% | J6: $28,092,684.33 | K6: $1,984,872.00
A7: 66302015050 | B7: $0.00 | C7: $0.00 | D7: $0.00 | E7: $0.00 | F7: $0.00 | G7: $0.00 | H7: $4,120,663.80 | I7: 0.000000% | J7: $471,077.01 | K7: $0.00
A8: 66302020601 | B8: $0.00 | C8: $9,963,685.06 | D8: $0.00 | E8: $0.00 | F8: $0.00 | G8: $9,963,685.06 | H8: $553,634,634.54 | I8: 1.799686% | J8: $51,563,589.32 | K8: $927,982.70
A9: 66302020602 | B9: $0.00 | C9: $9,963,685.06 | D9: $0.00 | E9: $0.00 | F9: $0.00 | G9: $9,963,685.06 | H9: $553,634,634.54 | I9: 1.799686% | J9: $51,563,589.32 | K9: $927,982.70
A10: 66302020603 | B10: $0.00 | C10: $9,963,685.06 | D10: $0.00 | E10: $0.00 | F10: $0.00 | G10: $9,963,685.06 | H10: $553,634,634.54 | I10: 1.799686% | J10: $51,563,589.32 | K10: $927,982.70
A11: 66302020604 | B11: $0.00 | C11: $9,963,685.06 | D11: $0.00 | E11: $0.00 | F11: $0.00 | G11: $9,963,685.06 | H11: $553,634,634.54 | I11: 1.799686% | J11: $51,563,589.32 | K11: $927,982.70
A12: 66302030001 | B12: $0.00 | C12: $0.00 | D12: $0.00 | E12: $0.00 | F12: $0.00 | G12: $0.00 | H12: $0.00 | I12: 0.000000% | J12: $0.00 | K12: $0.00
... A56: 66302076404 | B56: $0.00 | C56: $0.00 | D56: $0.00 | E56: $180.87 | F56: $0.00 | G56: $279.53 | H56: $263,085.60 | I56: 0.106250% | J56: $65,771.40 | K56: $69.88

Sheet Icyte Report
A2: period | B2: 2024-07 | D2: Select the period to fetch the values
A3: prior period | B3: 2024-06
E4: calc_type | F4: rcp_sales | G4: rcp_sales | H4: rcp_sales_12m | I4: rcp_elig_adj | J4: rcp_elig_adj | K4: rcp_elig_adj_12m | L4: non_rcp_cbk_sales | M4: non_rcp_cbk_sales | N4: non_rcp_cbk_sales_12m | O4: ds_gross_sales_pre | P4: ds_gross_sales_pre | Q4: ds_gross_sales_12m_pre | R4: ds_gross_sales_12m | S4: rcp_amp_elig_12m | T4: rcp_ratio | U4: ds_trans_inelig | V4: ds_trans_inelig | W4: ds_gross_sales | X4: ds_gross_sales | Y4: ds_inelig_state | Z4: ds_inelig_state | AA4: ds_inelig_cot | AB4: ds_inelig_cot | AC4: ds_inelig_cont | AD4: ds_inelig_cont | AE4: ds_free_goods | AF4: ds_free_goods | AG4: ds_inelig_340b | AH4: ds_inelig_340b | AI4: ds_inelig_state_12m | AJ4: ds_inelig_state_12m | AK4: ds_inelig_cot_12m | AL4: ds_inelig_cot_12m | AM4: ds_inelig_cont_12m | AN4: ds_inelig_cont_12m | AO4: ds_free_goods_12m | AP4: ds_free_goods_12m | AQ4: ds_inelig_340b_12m | AR4: ds_inelig_340b_12m | AS4: ds_elig | AT4: ds_elig | AU4: ds_elig_adj | AV4: ds_elig_adj | AW4: ds_elig_adj_12m | AX4: ds_elig_adj_12m | AY4: ds_adj_elig | AZ4: ds_adj_elig | BA4: ds_adj_elig_12m | BB4: ds_adj_elig_12m | BC4: cbk_whl_inelig | BD4: cbk_whl_inelig | BE4: cbk_cont_inelig | BF4: cbk_cont_inelig | BG4: cbk_cont_inelig_12m | BH4: cbk_cont_inelig_12m | BI4: cbk_fss_inelig | BJ4: cbk_fss_inelig | BK4: cbk_fss_inelig_12m | BL4: cbk_state_inelig | BM4: cbk_state_inelig | BN4: cbk_state_inelig_12m | BO4: cbk_state_inelig_12m | BP4: cbk_cot_inelig | BQ4: cbk_cot_inelig | BR4: cbk_cot_inelig_12m | BS4: cbk_cot_inelig_12m | BT4: cbk_inelig | BU4: cbk_inelig | BV4: avg_ds_elig | BW4: indir_inelig_ratio | BX4: indir_smooth_inelig | BY4: indir_smooth_inelig | BZ4: amp_elig | CA4: amp_elig | CB4: cbk_elig | CC4: cbk_elig | CD4: cbk_elig_12m | CE4: ds_elig_12m | CF4: ds_elig_12m | CG4: indir_inelig_12m | CH4: indir_inelig_12m | CI4: _annual_weighted_wac | CJ4: cbk_inelig_12m | CK4: cbk_inelig_12m | CL4: amp_elig_12m | CM4: amp_elig_12m | CN4: reb_inelig | CO4: reb_inelig | CP4: reb_bfsf_elig | CQ4: reb_bfsf_elig | CR4: reb_fee_elig | CS4: reb_fee_elig | CT4: reb_elig | CU4: reb_elig | CV4: reb_elig_12m | CW4: reb_fee_elig_12m | CX4: reb_fee_allocation | CY4: reb_fees_factored_12m | CZ4: pc_elig_12m | DA4: pc_elig_ratio | DB4: pc_smooth_elig | DC4: nonwhl_ppd | DD4: amp_net_elig | DE4: amp_net_elig | DF4: amp_ndc9 | DG4: amp_ndc9 | DH4: _month_end_wac | DI4: ramp | DJ4: ramp | DK4: mamp_v_wac | DL4: mamp_calculated | DM4: mamp_calculated | DN4: qamp | DO4: qamp | DP4: qamp_totals | DQ4: qamp_totals | DR4: qamp_fp | DS4: qamp_fp | DT4: qamp_calculated | DU4: qamp_calculated | DV4: rqamp | DW4: rqamp | DX4: _quarter_end_wac
A5: NDC11 | B5: NDC9 | C5: Product Description | D5: Calc Period | E5: Calculation Type (5i/RCP) | F5: RCP Sales (70/30 calc)(dollars) | G5: RCP Sales (70/30 calc)(units) | H5: RCP Sales - 12 Months (70/30 Calc)(units) | I5: RCP Eligible Adjustments(dollars) | J5: RCP Eligible Adjustments(units) | K5: RCP Eligible Adjustments 12 months(units) | L5: Non RCP Chargebacks (70/30 Calc)(dollars) | M5: Non RCP Chargebacks (70/30 Calc)(units) | N5: Non RCP Chargebacks - 12 Months (70/30 Calc)(units) | O5: Gross Sales (70/30 Calc)(dollars) | P5: Gross Sales (70/30 Calc)(units) | Q5: Gross Sales - 12 Months (70/30 Calc)(units) | R5: Gross Sales - 12 Months (70/30 Calc)(units) | S5: Net RCP Sales (70/30 Calc)(units) | T5: RCP 70/30 Calc Ratio(units) | U5: Direct Sales Ineligible Transactions(dollars) | V5: Direct Sales Ineligible Transactions(units) | W5: Gross Sales(dollars) | X5: Gross Sales(units) | Y5: Direct Sales Ineligible State(dollars) | Z5: Direct Sales Ineligible State(units) | AA5: Direct Sales Ineligible COT(dollars) | AB5: Direct Sales Ineligible COT(units) | AC5: Direct Sales Ineligible Contract(dollars) | AD5: Direct Sales Ineligible Contract(units) | AE5: Free Goods(dollars) | AF5: Free Goods(units) | AG5: RHAP Sales(dollars) | AH5: RHAP Sales(units) | AI5: Direct Sales Ineligible State - 12 Months(dollars) | AJ5: Direct Sales Ineligible State - 12 Months(units) | AK5: Direct Sales Ineligible COT - 12 Months(dollars) | AL5: Direct Sales Ineligible COT - 12 Months(units) | AM5: Direct Sales Ineligible Contract - 12 Months(dollars) | AN5: Direct Sales Ineligible Contract - 12 Months(units) | AO5: Free Goods - 12 Months(dollars) | AP5: Free Goods - 12 Months(units) | AQ5: RHAP Sales - 12 Months(dollars) | AR5: RHAP Sales - 12 Months(units) | AS5: Eligible Direct Sales(dollars) | AT5: Eligible Direct Sales(units) | AU5: Direct Sales Eligible Adjustments(dollars) | AV5: Direct Sales Eligible Adjustments(units) | AW5: Direct Sales Eligible Adjustments - 12 Months(dollars) | AX5: Direct Sales Eligible Adjustments - 12 Months(units) | AY5: Eligible Adjusted Direct Sales(dollars) | AZ5: Eligible Adjusted Direct Sales(units) | BA5: Eligible Adjusted Direct Sales - 12 Months(dollars) | BB5: Eligible Adjusted Direct Sales - 12 Months(units) | BC5: Ineligible Indirect Sales - non-domestic whl(dollars) | BD5: Ineligible Indirect Sales - non-domestic whl(units) | BE5: Ineligible Indirect Sales - Contract(dollars) | BF5: Ineligible Indirect Sales - Contract(units) | BG5: Ineligible Indirect Sales - Contract - 12 Months(dollars) | BH5: Ineligible Indirect Sales - Contract - 12 Months(units) | BI5: Ineligible Indirect Sales -FSS Contract(dollars) | BJ5: Ineligible Indirect Sales -FSS Contract(units) | BK5: Ineligible Indirect Sales - FSS Contract - 12 Months(units) | BL5: Ineligible Indirect Sales - State(dollars) | BM5: Ineligible Indirect Sales - State(units) | BN5: Ineligible Indirect Sales - State - 12 Months(dollars) | BO5: Ineligible Indirect Sales - State - 12 Months(units) | BP5: Ineligible Indirect Sales - COT(dollars) | BQ5: Ineligible Indirect Sales - COT(units) | BR5: Ineligible Indirect Sales - COT - 12 Months(dollars) | BS5: Ineligible Indirect Sales - COT - 12 Months(units) | BT5: Ineligible Indirect Sales(dollars) | BU5: Ineligible Indirect Sales(units) | BV5: Average Direct Sales Price(dollars) | BW5: Ineligible Indirect Sales Ratio(units) | BX5: Smoothed Ineligible Indirect Sales(dollars) | BY5: Smoothed Ineligible Indirect Sales(units) | BZ5: Eligible AMP Sales(dollars) | CA5: Eligible AMP Sales(units) | CB5: AMP Eligible Chargebacks(dollars) | CC5: AMP Eligible Chargebacks(units) | CD5: AMP Eligible Chargebacks - 12 Months(dollars) | CE5: Eligible Direct Sales - 12 Months(dollars) | CF5: Eligible Direct Sales - 12 Months(units) | CG5: Ineligible Indirect Sales - 12 Months(dollars) | CH5: Ineligible Indirect Sales - 12 Months(units) | CI5: Annual Weighted WAC(dollars) | CJ5: Ineligible CBK Sales - 12 Months(dollars) | CK5: Ineligible CBK Sales - 12 Months(units) | CL5: Eligible AMP Sales - 12 Months(dollars) | CM5: Eligible AMP Sales - 12 Months(units) | CN5: Ineligible Rebates - Cont, State, COT(dollars) | CO5: Ineligible Rebates - Cont, State, COT(units) | CP5: Eligible Bona Fide Service Fees(dollars) | CQ5: Eligible Bona Fide Service Fees(units) | CR5: Eligible Fees(dollars) | CS5: Eligible Fees(units) | CT5: Eligible Rebates(dollars) | CU5: Eligible Rebates(units) | CV5: AMP Eligible rebates - 12 months(dollars) | CW5: AMP Eligible Fee Rebates - 12 Months(dollars) | CX5: Fee Allocation Ratio(units) | CY5: Rebate Fees(dollars) | CZ5: Eligible Price Concessions - 12 Months(dollars) | DA5: Price Concession Ratio(dollars) | DB5: Smoothed Eligible Price Concessions(dollars) | DC5: Non-wholesaler prompt pay - Customary(dollars) | DD5: Eligible AMP Net Sales(dollars) | DE5: Eligible AMP Net Sales(units) | DF5: Calculated AMP - NDC9(dollars) | DG5: Calculated AMP - NDC9(units) | DH5: Month End WAC(dollars) | DI5: Monthly AMP(dollars) | DJ5: Monthly AMP(units) | DK5: Monthly AMP Greater Than WAC(dollars) | DL5: Calculated Monthly AMP(dollars) | DM5: Calculated Monthly AMP(units) | DN5: Calculated Quarterly AMP(dollars) | DO5: Calculated Quarterly AMP(units) | DP5: QAMP Totals(dollars) | DQ5: QAMP Totals(units) | DR5: QAMP False Positive Test(dollars) | DS5: QAMP False Positive Test(units) | DT5: Calculated Quarterly AMP(dollars) | DU5: Calculated Quarterly AMP(units) | DV5: Quarterly AMP(dollars) | DW5: Quarterly AMP(units) | DX5: Quarter End WAC(dollars)
A6: 66302001401 | B6: 663020014 | C6: Unituxin (dinutuximab) for Injection, for IV Use | D6: 2024-07 | E6: 5i | F6: 0 | G6: 0 | H6: 0 | I6: 0 | J6: 0 | K6: 0 | L6: -49051.28 | M6: -40 | N6: 250 | O6: 15598314 | P6: 4500 | Q6: 62000 | R6: 0 | S6: -250 | T6: -0.0040322581 | U6: 0 | V6: 0 | W6: 15598314 | X6: 4500 | Y6: 0 | Z6: 0 | AA6: 0 | AB6: 0 | AC6: 0 | AD6: 0 | AE6: 0 | AF6: 0 | AG6: 0 | AH6: 0 | AI6: 0 | AJ6: 0 | AK6: 0 | AL6: 0 | AM6: 0 | AN6: 0 | AO6: 0 | AP6: 0 | AQ6: 0 | AR6: 0 | AS6: 15598314 | AT6: 4500 | AU6: 0 | AV6: 0 | AW6: 0 | AX6: 0 | AY6: 15598314 | AZ6: 4500 | BA6: 206323229 | BB6: 62000 | BC6: 0 | BD6: 0 | BE6: -138651.68 | BF6: -40 | BG6: 796021.26 | BH6: 250 | BI6: 0 | BJ6: 0 | BK6: 0 | BL6: 0 | BM6: 0 | BN6: 0 | BO6: 0 | BP6: 0 | BQ6: 0 | BR6: 0 | BS6: 0 | BT6: -138651.68 | BU6: -40 | BV6: 3466.292 | BW6: 0.0040322581 | BX6: 62896.427 | BY6: 18.145161 | BZ6: 15535418 | CA6: 4481.8548 | CB6: 0 | CC6: 0 | CD6: 0 | CE6: 206323229 | CF6: 62000 | CG6: 796021.26 | CH6: 250 | CI6: 3335.7613 | CJ6: 833940.32 | CK6: 250 | CL6: 2.0548929e+08 | CM6: 61750 | CN6: 0 | CO6: 0 | CP6: 0 | CQ6: 0 | CR6: 0 | CS6: 0 | CT6: 0 | CU6: 0 | CV6: 0 | CW6: 0 | CX6: 1 | CY6: 0 | CZ6: 0 | DA6: 0 | DB6: 0 | DC6: 310708.35 | DD6: 15224709 | DE6: 4481.8548 | DF6: 3396.9662 | DG6: 4481.855 | DH6: 3466.292 | DI6: 3396.9662 | DJ6: 4481.855 | DK6: 0 | DL6: 15224709 | DM6: 4481.8548 | DN6: 3396.9662 | DO6: 13935.948 | DP6: 47339945 | DQ6: 13935.948 | DR6: 3396.9662 | DS6: 13935.948 | DT6: 3396.9662 | DU6: 13935.948 | DV6: 3396.9662 | DW6: 13935.948 | DX6: 3466.292
A7: 66302010101 | B7: 663020101 | C7: REMODULIN 1.0MG/ML 20ML VIAL | D7: 2024-07 | E7: 5i | F7: 0 | G7: 0 | H7: 0 | I7: 0 | J7: 0 | K7: 0 | L7: 82414.34 | M7: 1840 | N7: 25940 | O7: 3208766.4 | P7: 50400 | Q7: 762101.55 | R7: 0 | S7: -25940 | T7: -0.034037459 | U7: 0 | V7: 0 | W7: 3208766.4 | X7: 60600 | Y7: 0 | Z7: 0 | AA7: 0 | AB7: 0 | AC7: 0 | AD7: 0 | AE7: 0 | AF7: 10200 | AG7: 0 | AH7: 0 | AI7: 0 | AJ7: 0 | AK7: 0 | AL7: 0 | AM7: 0 | AN7: 0 | AO7: 0 | AP7: 140400 | AQ7: 163367.67 | AR7: 51317 | AS7: 3208766.4 | AT7: 50400 | AU7: 0 | AV7: 0 | AW7: 0 | AX7: 0 | AY7: 3208766.4 | AZ7: 50400 | BA7: 48554078 | BB7: 772815.55 | BC7: 0 | BD7: 0 | BE7: 105685.56 | BF7: 1660 | BG7: 1561090.3 | BH7: 24520 | BI7: 11459.88 | BJ7: 180 | BK7: 1420 | BL7: 0 | BM7: 0 | BN7: 0 | BO7: 0 | BP7: 0 | BQ7: 0 | BR7: 0 | BS7: 0 | BT7: 117145.44 | BU7: 1840 | BV7: 63.666 | BW7: 0.033565577 | BX7: 107704.1 | BY7: 1691.7051 | BZ7: 3101062.3 | CA7: 48708.295 | CB7: 0 | CC7: 0 | CD7: 0 | CE7: 48554078 | CF7: 772815.55 | CG7: 1651496 | CH7: 25940 | CI7: 63.666 | CJ7: 1651496 | CK7: 25940 | CL7: 46902582 | CM7: 746875.55 | CN7: 0 | CO7: 0 | CP7: 0 | CQ7: 0 | CR7: 220539.02 | CS7: 43300 | CT7: 88623.072 | CU7: 17400 | CV7: 841027.86 | CW7: 2720626.8 | CX7: 0.99816256 | CY7: 3555110.4 | CZ7: 3555110.4 | DA7: 0.075797755 | DB7: 235053.56 | DC7: 62021.246 | DD7: 2803987.5 | DE7: 48708.295 | DF7: 57.56694 | DG7: 48708.295 | DH7: 63.666 | DI7: 57.56694 | DJ7: 48708.295 | DK7: 0 | DL7: 2803987.5 | DM7: 48708.295 | DN7: 57.081045 | DO7: 194585.35 | DP7: 11107135 | DQ7: 194585.35 | DR7: 57.081045 | DS7: 194585.35 | DT7: 57.081045 | DU7: 194585.35 | DV7: 57.081045 | DW7: 194585.35 | DX7: 63.666
A8: 66302010201 | B8: 663020102 | C8: REMODULIN 2.5MG/ML 20ML VIAL | D8: 2024-07 | E8: 5i | F8: 0 | G8: 0 | H8: 0 | I8: 0 | J8: 0 | K8: 0 | L8: 86048.81 | M8: 760 | N8: 16900 | O8: 4934115 | P8: 31000 | Q8: 406286.8 | R8: 0 | S8: -16900 | T8: -0.041596232 | U8: 0 | V8: 0 | W8: 4934115 | X8: 35600 | Y8: 0 | Z8: 0 | AA8: 0 | AB8: 0 | AC8: 0 | AD8: 0 | AE8: 0 | AF8: 4600 | AG8: 0 | AH8: 0 | AI8: 0 | AJ8: 0 | AK8: 0 | AL8: 0 | AM8: 0 | AN8: 0 | AO8: 0 | AP8: 81200 | AQ8: 98971.906 | AR8: 12436 | AS8: 4934115 | AT8: 31000 | AU8: 0 | AV8: 0 | AW8: 0 | AX8: 0 | AY8: 4934115 | AZ8: 31000 | BA8: 64676988 | BB8: 407586.8 | BC8: 0 | BD8: 0 | BE8: 85949.1 | BF8: 540 | BG8: 1995929.1 | BH8: 12540 | BI8: 35016.3 | BJ8: 220 | BK8: 4360 | BL8: 0 | BM8: 0 | BN8: 0 | BO8: 0 | BP8: 0 | BQ8: 0 | BR8: 0 | BS8: 0 | BT8: 120965.4 | BU8: 760 | BV8: 159.165 | BW8: 0.041463561 | BX8: 204585.98 | BY8: 1285.3704 | BZ8: 4729529 | CA8: 29714.63 | CB8: 0 | CC8: 0 | CD8: 0 | CE8: 64676988 | CF8: 407586.8 | CG8: 2689888.5 | CH8: 16900 | CI8: 159.165 | CJ8: 2689888.5 | CK8: 16900 | CL8: 61987100 | CM8: 390686.8 | CN8: 0 | CO8: 0 | CP8: 0 | CQ8: 0 | CR8: 253136.18 | CS8: 8019480 | CT8: 145158.48 | CU8: 11400 | CV8: 1421661.8 | CW8: 3375827.8 | CX8: 0.98930289 | CY8: 4746170.3 | CZ8: 4746170.3 | DA8: 0.076567065 | DB8: 362126.16 | DC8: 94590.58 | DD8: 4272812.3 | DE8: 29714.63 | DF8: 143.7949 | DG8: 29714.63 | DH8: 159.165 | DI8: 143.7949 | DJ8: 29714.63 | DK8: 0 | DL8: 4272812.3 | DM8: 29714.63 | DN8: 143.99 | DO8: 96244.056 | DP8: 13858182 | DQ8: 96244.056 | DR8: 143.99 | DS8: 96244.056 | DT8: 143.99 | DU8: 96244.056 | DV8: 143.99 | DW8: 96244.056 | DX8: 159.165
A9: 66302010501 | B9: 663020105 | C9: REMODULIN 5.0MG/ML 20ML VIAL | D9: 2024-07 | E9: 5i | F9: 0 | G9: 0 | H9: 0 | I9: 0 | J9: 0 | K9: 0 | L9: 126995.88 | M9: 560 | N9: 15400 | O9: 8340246 | P9: 26200 | Q9: 390768.4 | R9: 0 | S9: -15400 | T9: -0.039409533 | U9: 0 | V9: 0 | W9: 8340246 | X9: 31200 | Y9: 0 | Z9: 0 | AA9: 0 | AB9: 0 | AC9: 0 | AD9: 0 | AE9: 0 | AF9: 5000 | AG9: 0 | AH9: 0 | AI9: 0 | AJ9: 0 | AK9: 0 | AL9: 0 | AM9: 0 | AN9: 0 | AO9: 0 | AP9: 80500 | AQ9: 216719.06 | AR9: 13616 | AS9: 8340246 | AT9: 26200 | AU9: 0 | AV9: 0 | AW9: 0 | AX9: 0 | AY9: 8340246 | AZ9: 26200 | BA9: 1.2448486e+08 | BB9: 396520.4 | BC9: 0 | BD9: 0 | BE9: 127332 | BF9: 400 | BG9: 3711727.8 | BH9: 11660 | BI9: 50932.8 | BJ9: 160 | BK9: 3740 | BL9: 0 | BM9: 0 | BN9: 0 | BO9: 0 | BP9: 0 | BQ9: 0 | BR9: 0 | BS9: 0 | BT9: 178264.8 | BU9: 560 | BV9: 318.33 | BW9: 0.03883785 | BX9: 323917.23 | BY9: 1017.5517 | BZ9: 8016328.8 | CA9: 25182.448 | CB9: 0 | CC9: 0 | CD9: 0 | CE9: 1.2448486e+08 | CF9: 396520.4 | CG9: 4902282 | CH9: 15400 | CI9: 318.33 | CJ9: 4902282 | CK9: 15400 | CL9: 1.1958257e+08 | CM9: 381120.4 | CN9: 0 | CO9: 0 | CP9: 0 | CQ9: 0 | CR9: 381996 | CS9: 8014600 | CT9: 331063.2 | CU9: 13000 | CV9: 3866436.2 | CW9: 5344888 | CX9: 0.99056795 | CY9: 9124442.5 | CZ9: 9124442.5 | DA9: 0.076302443 | DB9: 611665.47 | DC9: 160326.58 | DD9: 7244336.7 | DE9: 25182.448 | DF9: 287.67404 | DG9: 25182.448 | DH9: 318.33 | DI9: 287.67404 | DJ9: 25182.448 | DK9: 0 | DL9: 7244336.7 | DM9: 25182.448 | DN9: 286.02632 | DO9: 97384.504 | DP9: 27854531 | DQ9: 97384.504 | DR9: 286.02632 | DS9: 97384.504 | DT9: 286.02632 | DU9: 97384.504 | DV9: 286.02632 | DW9: 97384.504 | DX9: 318.33
A10: 66302011001 | B10: 663020110 | C10: REMODULIN 10.0MG/ML 20ML VIAL | D10: 2024-07 | E10: 5i | F10: 0 | G10: 0 | H10: 0 | I10: 0 | J10: 0 | K10: 0 | L10: 619434.18 | M10: 1620 | N10: 24068.5 | O10: 23811084 | P10: 37400 | Q10: 496264.2 | R10: 0 | S10: -24068.5 | T10: -0.048499368 | U10: 0 | V10: 0 | W10: 23811084 | X10: 42800 | Y10: 0 | Z10: 0 | AA10: 0 | AB10: 0 | AC10: 0 | AD10: 0 | AE10: 0 | AF10: 5400 | AG10: 0 | AH10: 0 | AI10: 0 | AJ10: 0 | AK10: 0 | AL10: 0 | AM10: 0 | AN10: 0 | AO10: 0 | AP10: 84300 | AQ10: 340995.1 | AR10: 10712 | AS10: 23811084 | AT10: 37400 | AU10: 0 | AV10: 0 | AW10: 0 | AX10: 0 | AY10: 23811084 | AZ10: 37400 | BA10: 3.1603344e+08 | BB10: 498836.2 | BC10: 0 | BD10: 0 | BE10: 904057.2 | BF10: 1420 | BG10: 12720467 | BH10: 19980 | BI10: 127332 | BJ10: 200 | BK10: 4088.5 | BL10: 0 | BM10: 0 | BN10: 0 | BO10: 0 | BP10: 0 | BQ10: 0 | BR10: 0 | BS10: 0 | BT10: 1031389.2 | BU10: 1620 | BV10: 636.66 | BW10: 0.048249305 | BX10: 1148868.3 | BY10: 1804.524 | BZ10: 22662216 | CA10: 35595.476 | CB10: 0 | CC10: 0 | CD10: 0 | CE10: 3.1603344e+08 | CF10: 498836.2 | CG10: 15323451 | CH10: 24068.5 | CI10: 636.66 | CJ10: 15323451 | CK10: 24068.5 | CL10: 3.0070999e+08 | CM10: 474767.7 | CN10: 0 | CO10: 0 | CP10: 0 | CQ10: 0 | CR10: 1016618.7 | CS10: 64016760 | CT10: 926976.96 | CU10: 18200 | CV10: 10212026 | CW10: 12588551 | CX10: 0.99180392 | CY10: 22613702 | CZ10: 22613702 | DA10: 0.075201034 | DB10: 1704222 | DC10: 453244.31 | DD10: 20504749 | DE10: 35595.476 | DF10: 576.04931 | DG10: 35595.476 | DH10: 636.66 | DI10: 576.04931 | DJ10: 35595.476 | DK10: 0 | DL10: 20504749 | DM10: 35595.476 | DN10: 576.28378 | DO10: 120776.92 | DP10: 69601782 | DQ10: 120776.92 | DR10: 576.28378 | DS10: 120776.92 | DT10: 576.28378 | DU10: 120776.92 | DV10: 576.28377 | DW10: 120776.93 | DX10: 636.66
A11: 66302020601 | B11: 663020206 | C11: TYVASO INH SOL 2.9ML 28 AMPULE STARTER KIT | D11: 2024-07 | E11: 5i | F11: 0 | G11: 0 | H11: 0 | I11: 0 | J11: 0 | K11: 0 | L11: 142753.64 | M11: 730.8 | N11: 150533.2 | O11: 4664394 | P11: 16240 | Q11: 2291185.6 | R11: 0 | S11: -150533.2 | T11: -0.065701007 | U11: 0 | V11: 0 | W11: 4664394 | X11: 20300 | Y11: 0 | Z11: 0 | AA11: 0 | AB11: 0 | AC11: 0 | AD11: 0 | AE11: 0 | AF11: 4060 | AG11: 0 | AH11: 0 | AI11: 0 | AJ11: 0 | AK11: 0 | AL11: 0 | AM11: 0 | AN11: 0 | AO11: 0 | AP11: 410988 | AQ11: 0 | AR11: 0 | AS11: 4664394 | AT11: 16240 | AU11: 0 | AV11: 0 | AW11: 0 | AX11: 0 | AY11: 4664394 | AZ11: 16240 | BA11: 5.8385172e+08 | BB11: 2291185.6 | BC11: 0 | BD11: 0 | BE11: 23321.97 | BF11: 81.2 | BG11: 11430153 | BH11: 45193.6 | BI11: 186575.76 | BJ11: 649.6 | BK11: 105339.6 | BL11: 0 | BM11: 0 | BN11: 0 | BO11: 0 | BP11: 0 | BQ11: 0 | BR11: 0 | BS11: 0 | BT11: 209897.73 | BU11: 730.8 | BV11: 287.21638 | BW11: 0.065701007 | BX11: 306455.38 | BY11: 1066.9843 | BZ11: 4357938.6 | CA11: 15173.016 | CB11: 0 | CC11: 0 | CD11: 0 | CE11: 5.8385172e+08 | CF11: 2291185.6 | CG11: 38089864 | CH11: 150533.2 | CI11: 281.608 | CJ11: 42391353 | CK11: 150533.2 | CL11: 5.4146037e+08 | CM11: 2140652.4 | CN11: 0 | CO11: 0 | CP11: 0 | CQ11: 0 | CR11: 59237.804 | CS11: 10312.4 | CT11: 41979.546 | CU11: 7308 | CV11: 4513527.3 | CW11: 6688971.5 | CX11: 0.95402398 | CY11: 10687452 | CZ11: 10687452 | DA11: 0.019738199 | DB11: 86017.86 | DC11: 87158.772 | DD11: 4184762 | DE11: 15173.016 | DF11: 249.86806 | DG11: 166903.17 | DH11: 287.21638 | DI11: 249.86806 | DJ11: 166903.17 | DK11: 0 | DL11: 41703772 | DM11: 166903.17 | DN11: 250.03448 | DO11: 531909 | DP11: 1.3299559e+08 | DQ11: 531909 | DR11: 250.03448 | DS11: 531909 | DT11: 250.03448 | DU11: 531909 | DV11: 250.03448 | DW11: 531909 | DX11: 287.21638
A12: 66302020602 | B12: 663020206 | C12: TYVASO INH SOL 2.9ML 28 AMPULE REFILL KIT | D12: 2024-07 | E12: 5i | F12: 0 | G12: 0 | H12: 0 | I12: 0 | J12: 0 | K12: 0 | L12: 1703520.3 | M12: 9906.4 | N12: 150533.2 | O12: 41185116 | P12: 159964 | Q12: 2291185.6 | R12: 0 | S12: -150533.2 | T12: -0.065701007 | U12: 0 | V12: 0 | W12: 41185116 | X12: 193256 | Y12: 0 | Z12: 0 | AA12: 0 | AB12: 0 | AC12: 0 | AD12: 0 | AE12: 0 | AF12: 33292 | AG12: 0 | AH12: 0 | AI12: 0 | AJ12: 0 | AK12: 0 | AL12: 0 | AM12: 0 | AN12: 0 | AO12: 0 | AP12: 410988 | AQ12: 0 | AR12: 0 | AS12: 41185116 | AT12: 159964 | AU12: 0 | AV12: 0 | AW12: 0 | AX12: 0 | AY12: 41185116 | AZ12: 159964 | BA12: 5.8385172e+08 | BB12: 2291185.6 | BC12: 0 | BD12: 0 | BE12: 606278.35 | BF12: 2354.8 | BG12: 11430153 | BH12: 45193.6 | BI12: 1944271.9 | BJ12: 7551.6 | BK12: 105339.6 | BL12: 0 | BM12: 0 | BN12: 0 | BO12: 0 | BP12: 0 | BQ12: 0 | BR12: 0 | BS12: 0 | BT12: 2550550.3 | BU12: 9906.4 | BV12: 257.4649 | BW12: 0.065701007 | BX12: 2705903.5 | BY12: 10509.796 | BZ12: 38479212 | CA12: 149454.2 | CB12: 0 | CC12: 0 | CD12: 0 | CE12: 5.8385172e+08 | CF12: 2291185.6 | CG12: 38089864 | CH12: 150533.2 | CI12: 252.43744 | CJ12: 38000216 | CK12: 150533.2 | CL12: 5.458515e+08 | CM12: 2140652.4 | CN12: 0 | CO12: 0 | CP12: 0 | CQ12: 0 | CR12: 497984.49 | CS12: 96709.2 | CT12: 342860.86 | CU12: 66584 | CV12: 4513527.3 | CW12: 6688971.5 | CX12: 0.95402398 | CY12: 10687452 | CZ12: 10687452 | DA12: 0.019579414 | DB12: 753400.41 | DC12: 769584.24 | DD12: 36956227 | DE12: 149454.2 | DF12: 249.86806 | DG12: 166903.17 | DH12: 257.4649 | DI12: 249.86806 | DJ12: 166903.17 | DK12: 0 | DL12: 41703772 | DM12: 166903.17 | DN12: 250.03448 | DO12: 531909 | DP12: 1.3299559e+08 | DQ12: 531909 | DR12: 250.03448 | DS12: 531909 | DT12: 250.03448 | DU12: 531909 | DV12: 250.03448 | DW12: 531909 | DX12: 257.4649
